Workbook

Sheet Pinacolada cocktail
B9: FICHE TECHNIQUE
B11: Cocktail
B13: Piña colada
B15: Nombre de verres: | C15: 1
B17: Prix de vente TTC : | C17: =(C18*F38)+F38 -> 15.016182
B18: Taux TVA : | C18: 0.16
B20: Mode d'élaboration :
B21: Shaker
B22: Verre à mélange
B23: Direct au verre
B25: Type de verre utilisé: | C25: Verre à cocktail
B26: Article | C26: Unité | D26: Unités nécessaires | E26: Coût d'achat HT à l'unité | F26: Prix de revient HT
B27: Jus d'Ananas-100 | C27: =_xlfn.XLOOKUP(Tableau5712314161828[[#This Row],[Article]],'Liste des fournisseurs'!$B$12:$B$307,'Liste des fournisseurs'!$C$12:$C$307,"") -> cl | D27: 12 | E27: =_xlfn.XLOOKUP(Tableau5712314161828[[#This Row],[Article]],'Liste des fournisseurs'!$B$12:$B$307,'Liste des fournisseurs'!$F$12:$F$307,"") -> 0.0286 | F27: =IFERROR(Tableau5712314161828[[#This Row],[Coût d''achat HT à l''unité]]*Tableau5712314161828[[#This Row],[Unités nécessaires]],"") -> 0.3432
B28: Lait de Coco | C28: =_xlfn.XLOOKUP(Tableau5712314161828[[#This Row],[Article]],'Liste des fournisseurs'!$B$12:$B$307,'Liste des fournisseurs'!$C$12:$C$307,"") -> cl | D28: 5 | E28: =_xlfn.XLOOKUP(Tableau5712314161828[[#This Row],[Article]],'Liste des fournisseurs'!$B$12:$B$307,'Liste des fournisseurs'!$F$12:$F$307,"") -> 0.0065 | F28: =IFERROR(Tableau5712314161828[[#This Row],[Coût d''achat HT à l''unité]]*Tableau5712314161828[[#This Row],[Unités nécessaires]],"") -> 0.0325
B29: Sirop de Sucre de canne-70 | C29: =_xlfn.XLOOKUP(Tableau5712314161828[[#This Row],[Article]],'Liste des fournisseurs'!$B$12:$B$307,'Liste des fournisseurs'!$C$12:$C$307,"") -> cl | D29: 1 | E29: =_xlfn.XLOOKUP(Tableau5712314161828[[#This Row],[Article]],'Liste des fournisseurs'!$B$12:$B$307,'Liste des fournisseurs'!$F$12:$F$307,"") -> 0.17142857 | F29: =IFERROR(Tableau5712314161828[[#This Row],[Coût d''achat HT à l''unité]]*Tableau5712314161828[[#This Row],[Unités nécessaires]],"") -> 0.17142857
B30: MONIN COCONUT FRUIT 1LTR | C30: =_xlfn.XLOOKUP(Tableau5712314161828[[#This Row],[Article]],'Liste des fournisseurs'!$B$12:$B$307,'Liste des fournisseurs'!$C$12:$C$307,"") -> cl | D30: 5 | E30: =_xlfn.XLOOKUP(Tableau5712314161828[[#This Row],[Article]],'Liste des fournisseurs'!$B$12:$B$307,'Liste des fournisseurs'!$F$12:$F$307,"") -> 0.16 | F30: =IFERROR(Tableau5712314161828[[#This Row],[Coût d''achat HT à l''unité]]*Tableau5712314161828[[#This Row],[Unités nécessaires]],"") -> 0.8
B31: BACARDI BLC 1L | C31: =_xlfn.XLOOKUP(Tableau5712314161828[[#This Row],[Article]],'Liste des fournisseurs'!$B$12:$B$307,'Liste des fournisseurs'!$C$12:$C$307,"") -> cl | D31: 5 | E31: =_xlfn.XLOOKUP(Tableau5712314161828[[#This Row],[Article]],'Liste des fournisseurs'!$B$12:$B$307,'Liste des fournisseurs'!$F$12:$F$307,"") -> 0.155 | F31: =IFERROR(Tableau5712314161828[[#This Row],[Coût d''achat HT à l''unité]]*Tableau5712314161828[[#This Row],[Unités nécessaires]],"") -> 0.775
B32: Total prix de revient HT | F32: =SUM(Tableau5712314161828[Prix de revient HT]) -> 2.1221286
B33: Prix de revient unitaire HT par portion produite : | F33: =F32/C15 -> 2.1221286
B34: Prix de revient unitaire HT par portion vendue : | F34: =F33 -> 2.1221286
B35: Coefficient de marge | F35: 6.1
B36: Taux de marque | F36: =(F38-F34)/F38 -> 0.83606557
B37: Référence taux de marque idéal | F37: 70%-90%
B38: Prix de vente HT | F38: =F34*F35 -> 12.944984
B39: Marge brute | F39: =F38-F34 -> 10.822856
B41: Technique de prépartion
B42: Dans un shaker, versez le rhum blanc, le jus d’ananas, le lait de coco et le sirop de canne Canadou.
B43: Secouez énergiquement pendant 1 minute afin de bien les mélanger.
B44: Versez le mélange du shaker dans votre verre long drink.

Sheet PinaColada mocktail
A7: FICHE TECHNIQUE
A9: Mocktail
A11: Virgin Piña Colada
A13: Nombre de verres: | B13: 1
A15: Prix de vente TTC : | B15: =(B16*E37)+E37 -> 10.172239
A16: Taux TVA : | B16: 0.16
A18: Mode d'élaboration :
A19: Shaker
A20: Verre à mélange
A21: Direct au verre
A23: Type de verre utilisé: | B23: Verre à cocktail
A24: Article | B24: Unité | C24: Unités nécessaires | D24: Coût d'achat HT à l'unité | E24: Prix de revient HT
A25: Jus d'Ananas-100 | B25: =_xlfn.XLOOKUP(Tableau57123141618[[#This Row],[Article]],'Liste des fournisseurs'!$B$12:$B$307,'Liste des fournisseurs'!$C$12:$C$307,"") -> cl | C25: 16 | D25: =_xlfn.XLOOKUP(Tableau57123141618[[#This Row],[Article]],'Liste des fournisseurs'!$B$12:$B$307,'Liste des fournisseurs'!$F$12:$F$307,"") -> 0.0286 | E25: =IFERROR(Tableau57123141618[[#This Row],[Coût d''achat HT à l''unité]]*Tableau57123141618[[#This Row],[Unités nécessaires]],"") -> 0.4576
A26: Lait de Coco | B26: =_xlfn.XLOOKUP(Tableau57123141618[[#This Row],[Article]],'Liste des fournisseurs'!$B$12:$B$307,'Liste des fournisseurs'!$C$12:$C$307,"") -> cl | C26: 5 | D26: =_xlfn.XLOOKUP(Tableau57123141618[[#This Row],[Article]],'Liste des fournisseurs'!$B$12:$B$307,'Liste des fournisseurs'!$F$12:$F$307,"") -> 0.0065 | E26: =IFERROR(Tableau57123141618[[#This Row],[Coût d''achat HT à l''unité]]*Tableau57123141618[[#This Row],[Unités nécessaires]],"") -> 0.0325
A28: Sirop de Sucre de canne-70 | B28: =_xlfn.XLOOKUP(Tableau57123141618[[#This Row],[Article]],'Liste des fournisseurs'!$B$12:$B$307,'Liste des fournisseurs'!$C$12:$C$307,"") -> cl | C28: 1 | D28: =_xlfn.XLOOKUP(Tableau57123141618[[#This Row],[Article]],'Liste des fournisseurs'!$B$12:$B$307,'Liste des fournisseurs'!$F$12:$F$307,"") -> 0.17142857 | E28: =IFERROR(Tableau57123141618[[#This Row],[Coût d''achat HT à l''unité]]*Tableau57123141618[[#This Row],[Unités nécessaires]],"") -> 0.17142857
A29: MONIN COCONUT FRUIT 1LTR | B29: =_xlfn.XLOOKUP(Tableau57123141618[[#This Row],[Article]],'Liste des fournisseurs'!$B$12:$B$307,'Liste des fournisseurs'!$C$12:$C$307,"") -> cl | C29: 5 | D29: =_xlfn.XLOOKUP(Tableau57123141618[[#This Row],[Article]],'Liste des fournisseurs'!$B$12:$B$307,'Liste des fournisseurs'!$F$12:$F$307,"") -> 0.16 | E29: =IFERROR(Tableau57123141618[[#This Row],[Coût d''achat HT à l''unité]]*Tableau57123141618[[#This Row],[Unités nécessaires]],"") -> 0.8
A30: Total prix de revient HT | E30: =SUM(Tableau57123141618[Prix de revient HT]) -> 1.4615286
A31: Prix de revient unitaire HT par portion produite : | E31: =E30/B13 -> 1.4615286
A32: Pourcentage moyen d'invendus : | B32: 0.2 | E32: =SUM(E25:E29) -> 1.4615286
A33: Prix de revient unitaire HT par portion vendue : | E33: =E31+B32*E31 -> 1.7538343
A34: Coefficient de marge | E34: 5
A35: Taux de marque | E35: =(E37-E33)/E37 -> 0.8
A36: Référence taux de marque idéal | E36: 70%-90%
A37: Prix de vente HT | E37: =E33*E34 -> 8.7691714
A38: Marge brute | E38: =E37-E33 -> 7.0153371
A40: Technique de prépartion
A41: Dans un shaker, versez le jus d’ananas Caraïbos, le lait de coco et le sirop de canne Canadou.
A42: Secouez énergiquement pendant 1 minute afin de bien les mélanger.
A43: Munissez-vous de votre verre long drink.
A44: Rafraîchissez le verre en y ajoutant une bonne quantité de glaçons.
A45: Versez-y le mélange du shaker.

Sheet Blue Hawaiian cocktail
A8: FICHE TECHNIQUE
A10: Cocktail
A12: Blue Hawaiian
A14: Nombre de verres: | B14: 1
A16: Prix de vente TTC : | B16: =(B17*E39)+E39 -> 14.998701
A17: Taux TVA : | B17: 0.16
A19: Mode d'élaboration :
A20: Shaker
A21: Verre à mélange
A22: Direct au verre
A24: Type de verre utilisé: | B24: Verre à cocktail
A25: Article | B25: Unité | C25: Unités nécessaires | D25: Coût d'achat HT à l'unité | E25: Prix de revient HT
A26: Jus d'Ananas-100 | B26: =_xlfn.XLOOKUP(Tableau5712314161820[[#This Row],[Article]],'Liste des fournisseurs'!$B$12:$B$307,'Liste des fournisseurs'!$C$12:$C$307,"") -> cl | C26: 12 | D26: =_xlfn.XLOOKUP(Tableau5712314161820[[#This Row],[Article]],'Liste des fournisseurs'!$B$12:$B$307,'Liste des fournisseurs'!$F$12:$F$307,"") -> 0.0286 | E26: =IFERROR(Tableau5712314161820[[#This Row],[Coût d''achat HT à l''unité]]*Tableau5712314161820[[#This Row],[Unités nécessaires]],"") -> 0.3432
A27: Lait de Coco | B27: =_xlfn.XLOOKUP(Tableau5712314161820[[#This Row],[Article]],'Liste des fournisseurs'!$B$12:$B$307,'Liste des fournisseurs'!$C$12:$C$307,"") -> cl | C27: 5 | D27: =_xlfn.XLOOKUP(Tableau5712314161820[[#This Row],[Article]],'Liste des fournisseurs'!$B$12:$B$307,'Liste des fournisseurs'!$F$12:$F$307,"") -> 0.0065 | E27: =IFERROR(Tableau5712314161820[[#This Row],[Coût d''achat HT à l''unité]]*Tableau5712314161820[[#This Row],[Unités nécessaires]],"") -> 0.0325
A28: BACARDI BLC 1L | B28: =_xlfn.XLOOKUP(Tableau5712314161820[[#This Row],[Article]],'Liste des fournisseurs'!$B$12:$B$307,'Liste des fournisseurs'!$C$12:$C$307,"") -> cl | C28: 3 | D28: =_xlfn.XLOOKUP(Tableau5712314161820[[#This Row],[Article]],'Liste des fournisseurs'!$B$12:$B$307,'Liste des fournisseurs'!$F$12:$F$307,"") -> 0.155 | E28: =IFERROR(Tableau5712314161820[[#This Row],[Coût d''achat HT à l''unité]]*Tableau5712314161820[[#This Row],[Unités nécessaires]],"") -> 0.465
A29: MONIN BLUE CURACAO 70CL | B29: =_xlfn.XLOOKUP(Tableau5712314161820[[#This Row],[Article]],'Liste des fournisseurs'!$B$12:$B$307,'Liste des fournisseurs'!$C$12:$C$307,"") -> cl | C29: 3 | D29: =_xlfn.XLOOKUP(Tableau5712314161820[[#This Row],[Article]],'Liste des fournisseurs'!$B$12:$B$307,'Liste des fournisseurs'!$F$12:$F$307,"") -> 0.17142857 | E29: =IFERROR(Tableau5712314161820[[#This Row],[Coût d''achat HT à l''unité]]*Tableau5712314161820[[#This Row],[Unités nécessaires]],"") -> 0.51428571
A30: MONIN COCONUT FRUIT 1LTR | B30: =_xlfn.XLOOKUP(Tableau5712314161820[[#This Row],[Article]],'Liste des fournisseurs'!$B$12:$B$307,'Liste des fournisseurs'!$C$12:$C$307,"") -> cl | C30: 5 | D30: =_xlfn.XLOOKUP(Tableau5712314161820[[#This Row],[Article]],'Liste des fournisseurs'!$B$12:$B$307,'Liste des fournisseurs'!$F$12:$F$307,"") -> 0.16 | E30: =IFERROR(Tableau5712314161820[[#This Row],[Coût d''achat HT à l''unité]]*Tableau5712314161820[[#This Row],[Unités nécessaires]],"") -> 0.8
B31: =_xlfn.XLOOKUP(Tableau5712314161820[[#This Row],[Article]],'Liste des fournisseurs'!$B$12:$B$307,'Liste des fournisseurs'!$C$12:$C$307,"") | D31: =_xlfn.XLOOKUP(Tableau5712314161820[[#This Row],[Article]],'Liste des fournisseurs'!$B$12:$B$307,'Liste des fournisseurs'!$F$12:$F$307,"") | E31: =IFERROR(Tableau5712314161820[[#This Row],[Coût d''achat HT à l''unité]]*Tableau5712314161820[[#This Row],[Unités nécessaires]],"")
A32: Total prix de revient HT | E32: =SUM(Tableau5712314161820[Prix de revient HT]) -> 2.1549857
A33: Prix de revient unitaire HT par portion produite : | E33: =E32/B14 -> 2.1549857
A34: Pourcentage moyen d'invendus : | B34: 0.2 | E34: =SUM(E26:E31) -> 2.1549857
A35: Prix de revient unitaire HT par portion vendue : | E35: =E33+B34*E33 -> 2.5859829
A36: Coefficient de marge | E36: 5
A37: Taux de marque | E37: =(E39-E35)/E39 -> 0.8
A38: Référence taux de marque idéal | E38: 70%-90%
A39: Prix de vente HT | E39: =E35*E36 -> 12.929914
A40: Marge brute | E40: =E39-E35 -> 10.343931
A42: Technique de prépartion
A43: Commencez par remplir votre shaker en y ajoutant des glaçons.
A44: Ajoutez ensuite, directement sur la glace, le rhum, le curaçao bleu, le sirop de canne, le lait de coco et enfin le jus d’ananas.
A45: Refermez le shaker.
A46: Secouez vigoureusement jusqu’à l’obtention d’un mélange bien homogène.
A47: Versez le mélange dans un verre de type cocktail ou tulipe qui est le contenant idéal pour accueillir ce délicieux nectar fruité.
A48: Retenez les glaçons à l’aide d’une passoire à cocktail.

Sheet Bora Bora mocktail
A9: FICHE TECHNIQUE
A11: Mocktail
A13: Bora Bora
A15: Nombre de verres: | B15: 1
A17: Prix de vente TTC : | B17: =(B18*E40)+E40 -> 8.079168
A18: Taux TVA : | B18: 0.16
A20: Mode d'élaboration :
A21: Shaker
A22: Verre à mélange
A23: Direct au verre
A25: Type de verre utilisé: | B25: Verre
A27: Article | B27: Unité | C27: Unités nécessaires | D27: Coût d'achat HT à l'unité | E27: Prix de revient HT
A28: Jus d'Ananas-100 | B28: =_xlfn.XLOOKUP(Tableau571231416182022[[#This Row],[Article]],'Liste des fournisseurs'!$B$12:$B$307,'Liste des fournisseurs'!$C$12:$C$307,"") -> cl | C28: 12 | D28: =_xlfn.XLOOKUP(Tableau571231416182022[[#This Row],[Article]],'Liste des fournisseurs'!$B$12:$B$307,'Liste des fournisseurs'!$F$12:$F$307,"") -> 0.0286 | E28: =IFERROR(Tableau571231416182022[[#This Row],[Coût d''achat HT à l''unité]]*Tableau571231416182022[[#This Row],[Unités nécessaires]],"") -> 0.3432
A29: Jus de fruit de la passion | B29: =_xlfn.XLOOKUP(Tableau571231416182022[[#This Row],[Article]],'Liste des fournisseurs'!$B$12:$B$307,'Liste des fournisseurs'!$C$12:$C$307,"") -> cl | C29: 2 | D29: =_xlfn.XLOOKUP(Tableau571231416182022[[#This Row],[Article]],'Liste des fournisseurs'!$B$12:$B$307,'Liste des fournisseurs'!$F$12:$F$307,"") -> 0.0286 | E29: =IFERROR(Tableau571231416182022[[#This Row],[Coût d''achat HT à l''unité]]*Tableau571231416182022[[#This Row],[Unités nécessaires]],"") -> 0.0572
A30: Jus de citron | B30: =_xlfn.XLOOKUP(Tableau571231416182022[[#This Row],[Article]],'Liste des fournisseurs'!$B$12:$B$307,'Liste des fournisseurs'!$C$12:$C$307,"") -> cl | C30: 2 | D30: =_xlfn.XLOOKUP(Tableau571231416182022[[#This Row],[Article]],'Liste des fournisseurs'!$B$12:$B$307,'Liste des fournisseurs'!$F$12:$F$307,"") -> 0.02 | E30: =IFERROR(Tableau571231416182022[[#This Row],[Coût d''achat HT à l''unité]]*Tableau571231416182022[[#This Row],[Unités nécessaires]],"") -> 0.04
A31: MONIN GRENADINE SIROP 1LTR | B31: =_xlfn.XLOOKUP(Tableau571231416182022[[#This Row],[Article]],'Liste des fournisseurs'!$B$12:$B$307,'Liste des fournisseurs'!$C$12:$C$307,"") -> cl | C31: 1 | D31: =_xlfn.XLOOKUP(Tableau571231416182022[[#This Row],[Article]],'Liste des fournisseurs'!$B$12:$B$307,'Liste des fournisseurs'!$F$12:$F$307,"") -> 0.14 | E31: =IFERROR(Tableau571231416182022[[#This Row],[Coût d''achat HT à l''unité]]*Tableau571231416182022[[#This Row],[Unités nécessaires]],"") -> 0.14
D32: =_xlfn.XLOOKUP(Tableau571231416182022[[#This Row],[Article]],'Liste des fournisseurs'!$B$12:$B$307,'Liste des fournisseurs'!$F$12:$F$307,"") | E32: =IFERROR(Tableau571231416182022[[#This Row],[Coût d''achat HT à l''unité]]*Tableau571231416182022[[#This Row],[Unités nécessaires]],"")
A33: Total prix de revient HT | E33: =SUM(Tableau571231416182022[Prix de revient HT]) -> 0.5804
A34: Prix de revient unitaire HT par portion produite : | E34: =E33/B15 -> 0.5804
A35: Pourcentage moyen d'invendus : | B35: 0.2 | E35: =SUM(E28:E32) -> 0.5804
A36: Prix de revient unitaire HT par portion vendue : | E36: =E34+B35*E34 -> 0.69648
A37: Coefficient de marge | E37: 10
A38: Taux de marque | E38: =(E40-E36)/E40 -> 0.9
A39: Référence taux de marque idéal | E39: 70%-90%
A40: Prix de vente HT | E40: =E36*E37 -> 6.9648
A41: Marge brute | E41: =E40-E36 -> 6.26832
A43: Technique de prépartion
A44: Versez les jus d’ananas, de fruits de la passion, de citron et la grenadine dans un shaker rempli de glace.
A45: Secouez énergiquement. Versez dans un verre en filtrant les glaçons.

Sheet Virgin Mojito
A9: FICHE TECHNIQUE
A11: Mocktail
A13: Virgin Mojito
A15: Nombre de verres: | B15: 1
A17: Prix de vente TTC : | B17: =(B18*E40)+E40 -> 10.148047
A18: Taux TVA : | B18: 0.16
A20: Mode d'élaboration :
A21: Shaker
A22: Verre à mélange
A23: Direct au verre
A25: Type de verre utilisé: | B25: Verre
A27: Article | B27: Unité | C27: Unités nécessaires | D27: Coût d'achat HT à l'unité | E27: Prix de revient HT
A28: Scheweppes Soda | B28: =_xlfn.XLOOKUP(Tableau57123141618202224[[#This Row],[Article]],'Liste des fournisseurs'!$B$12:$B$307,'Liste des fournisseurs'!$C$12:$C$307,"") -> cl | C28: 15 | D28: =_xlfn.XLOOKUP(Tableau57123141618202224[[#This Row],[Article]],'Liste des fournisseurs'!$B$12:$B$307,'Liste des fournisseurs'!$F$12:$F$307,"") -> 0.015151515 | E28: =IFERROR(Tableau57123141618202224[[#This Row],[Coût d''achat HT à l''unité]]*Tableau57123141618202224[[#This Row],[Unités nécessaires]],"") -> 0.22727273
A29: MONIN MOJITO MINT SIROP 1LT | B29: =_xlfn.XLOOKUP(Tableau57123141618202224[[#This Row],[Article]],'Liste des fournisseurs'!$B$12:$B$307,'Liste des fournisseurs'!$C$12:$C$307,"") -> cl | C29: 2 | D29: =_xlfn.XLOOKUP(Tableau57123141618202224[[#This Row],[Article]],'Liste des fournisseurs'!$B$12:$B$307,'Liste des fournisseurs'!$F$12:$F$307,"") -> 0.14 | E29: =IFERROR(Tableau57123141618202224[[#This Row],[Coût d''achat HT à l''unité]]*Tableau57123141618202224[[#This Row],[Unités nécessaires]],"") -> 0.28
A30: citron | B30: =_xlfn.XLOOKUP(Tableau57123141618202224[[#This Row],[Article]],'Liste des fournisseurs'!$B$12:$B$307,'Liste des fournisseurs'!$C$12:$C$307,"") -> unité | C30: 2 | D30: =_xlfn.XLOOKUP(Tableau57123141618202224[[#This Row],[Article]],'Liste des fournisseurs'!$B$12:$B$307,'Liste des fournisseurs'!$F$12:$F$307,"") -> 0.38496436 | E30: =IFERROR(Tableau57123141618202224[[#This Row],[Coût d''achat HT à l''unité]]*Tableau57123141618202224[[#This Row],[Unités nécessaires]],"") -> 0.76992872
A31: Sirop de Sucre de canne-70 | B31: =_xlfn.XLOOKUP(Tableau57123141618202224[[#This Row],[Article]],'Liste des fournisseurs'!$B$12:$B$307,'Liste des fournisseurs'!$C$12:$C$307,"") -> cl | C31: 2 | D31: =_xlfn.XLOOKUP(Tableau57123141618202224[[#This Row],[Article]],'Liste des fournisseurs'!$B$12:$B$307,'Liste des fournisseurs'!$F$12:$F$307,"") -> 0.17142857 | E31: =IFERROR(Tableau57123141618202224[[#This Row],[Coût d''achat HT à l''unité]]*Tableau57123141618202224[[#This Row],[Unités nécessaires]],"") -> 0.34285714
A32: Feuille de menthe | B32: =_xlfn.XLOOKUP(Tableau57123141618202224[[#This Row],[Article]],'Liste des fournisseurs'!$B$12:$B$307,'Liste des fournisseurs'!$C$12:$C$307,"") -> unité | C32: 8 | D32: =_xlfn.XLOOKUP(Tableau57123141618202224[[#This Row],[Article]],'Liste des fournisseurs'!$B$12:$B$307,'Liste des fournisseurs'!$F$12:$F$307,"") -> 0 | E32: =IFERROR(Tableau57123141618202224[[#This Row],[Coût d''achat HT à l''unité]]*Tableau57123141618202224[[#This Row],[Unités nécessaires]],"") -> 0
A33: Total prix de revient HT | E33: =SUM(Tableau57123141618202224[Prix de revient HT]) -> 1.6200586
A34: Prix de revient unitaire HT par portion produite : | E34: =E33/B15 -> 1.6200586
A35: Pourcentage moyen d'invendus : | B35: 0.2 | E35: =SUM(E28:E32) -> 1.6200586
A36: Prix de revient unitaire HT par portion vendue : | E36: =E34+B35*E34 -> 1.9440703
A37: Coefficient de marge | E37: 4.5
A38: Taux de marque | E38: =(E40-E36)/E40 -> 0.77777778
A39: Référence taux de marque idéal | E39: 70%-90%
A40: Prix de vente HT | E40: =E36*E37 -> 8.7483164
A41: Marge brute | E41: =E40-E36 -> 6.8042461
A44: Technique de prépartion
A45: Prenez un verre à mojito et pilez les dés de citron vert dedans.
A46: Déposez la menthe fraîche dans le verre et écrasez-la délicatement, sans la broyer.
A47: Ajoutez des glaçons jusqu’à la moitié.
A48: Ajoutez le sirop de Mojito, mélangez le tout et allongez de soda

Sheet Mojito
B9: FICHE TECHNIQUE
B11: Cocktail
B13: Mojito
B15: Nombre de verres: | C15: 1
B17: Prix de vente TTC : | C17: =(C18*F40)+F40 -> 14.931282
B18: Taux TVA : | C18: 0.16
B20: Mode d'élaboration :
B21: Shaker
B22: Verre à mélange
B23: Direct au verre
B25: Type de verre utilisé: | C25: Verre
B27: Article | C27: Unité | D27: Unités nécessaires | E27: Coût d'achat HT à l'unité | F27: Prix de revient HT
B28: RUM SAINT JAMES BLC 70CL | C28: =_xlfn.XLOOKUP(Tableau5712314161820222430[[#This Row],[Article]],'Liste des fournisseurs'!$B$12:$B$307,'Liste des fournisseurs'!$C$12:$C$307,"") -> cl | D28: 8 | E28: =_xlfn.XLOOKUP(Tableau5712314161820222430[[#This Row],[Article]],'Liste des fournisseurs'!$B$12:$B$307,'Liste des fournisseurs'!$F$12:$F$307,"") -> 0.17857143 | F28: =IFERROR(Tableau5712314161820222430[[#This Row],[Coût d''achat HT à l''unité]]*Tableau5712314161820222430[[#This Row],[Unités nécessaires]],"") -> 1.4285714
B29: Sirop de Sucre de canne-70 | C29: =_xlfn.XLOOKUP(Tableau5712314161820222430[[#This Row],[Article]],'Liste des fournisseurs'!$B$12:$B$307,'Liste des fournisseurs'!$C$12:$C$307,"") -> cl | D29: 2 | E29: =_xlfn.XLOOKUP(Tableau5712314161820222430[[#This Row],[Article]],'Liste des fournisseurs'!$B$12:$B$307,'Liste des fournisseurs'!$F$12:$F$307,"") -> 0.17142857 | F29: =IFERROR(Tableau5712314161820222430[[#This Row],[Coût d''achat HT à l''unité]]*Tableau5712314161820222430[[#This Row],[Unités nécessaires]],"") -> 0.34285714
B30: Scheweppes Soda | C30: =_xlfn.XLOOKUP(Tableau5712314161820222430[[#This Row],[Article]],'Liste des fournisseurs'!$B$12:$B$307,'Liste des fournisseurs'!$C$12:$C$307,"") -> cl | D30: 15 | E30: =_xlfn.XLOOKUP(Tableau5712314161820222430[[#This Row],[Article]],'Liste des fournisseurs'!$B$12:$B$307,'Liste des fournisseurs'!$F$12:$F$307,"") -> 0.015151515 | F30: =IFERROR(Tableau5712314161820222430[[#This Row],[Coût d''achat HT à l''unité]]*Tableau5712314161820222430[[#This Row],[Unités nécessaires]],"") -> 0.22727273
B31: citron | C31: =_xlfn.XLOOKUP(Tableau5712314161820222430[[#This Row],[Article]],'Liste des fournisseurs'!$B$12:$B$307,'Liste des fournisseurs'!$C$12:$C$307,"") -> unité | D31: 1 | E31: =_xlfn.XLOOKUP(Tableau5712314161820222430[[#This Row],[Article]],'Liste des fournisseurs'!$B$12:$B$307,'Liste des fournisseurs'!$F$12:$F$307,"") -> 0.38496436 | F31: =IFERROR(Tableau5712314161820222430[[#This Row],[Coût d''achat HT à l''unité]]*Tableau5712314161820222430[[#This Row],[Unités nécessaires]],"") -> 0.38496436
B32: Feuille de menthe | C32: =_xlfn.XLOOKUP(Tableau5712314161820222430[[#This Row],[Article]],'Liste des fournisseurs'!$B$12:$B$307,'Liste des fournisseurs'!$C$12:$C$307,"") -> unité | D32: 8 | E32: =_xlfn.XLOOKUP(Tableau5712314161820222430[[#This Row],[Article]],'Liste des fournisseurs'!$B$12:$B$307,'Liste des fournisseurs'!$F$12:$F$307,"") -> 0 | F32: =IFERROR(Tableau5712314161820222430[[#This Row],[Coût d''achat HT à l''unité]]*Tableau5712314161820222430[[#This Row],[Unités nécessaires]],"") -> 0
B33: Total prix de revient HT | F33: =SUM(Tableau5712314161820222430[Prix de revient HT]) -> 2.3836657
B34: Prix de revient unitaire HT par portion produite : | F34: =F33/C15 -> 2.3836657
B35: Pourcentage moyen d'invendus : | C35: 0.2 | F35: =SUM(F28:F32) -> 2.3836657
B36: Prix de revient unitaire HT par portion vendue : | F36: =F34+C35*F34 -> 2.8603988
B37: Coefficient de marge | F37: 4.5
B38: Taux de marque | F38: =(F40-F36)/F40 -> 0.77777778
B39: Référence taux de marque idéal | F39: 70%-90%
B40: Prix de vente HT | F40: =F36*F37 -> 12.871795
B41: Marge brute | F41: =F40-F36 -> 10.011396
B43: Technique de prépartion
B44: Dans un verre à Mojito, disposez 6 à 8 feuilles de menthe entières préalablement lavées et essuyées.
B45: Prenez votre demi citron vert.
B46: Coupez-le en dés.
B47: Déposez-le dans le verre.
B48: À l’aide d’un verre doseur, versez 2 cl de sirop de sucre de canne dans votre verre.
B49: Écrasez délicatement avec un pilon les dés de citron, les feuilles de menthe et le sucre de canne afin d’en extraire le jus.
B50: À l’aide d’un verre doseur, versez 4 cl de rhum blanc dans un verre à mojito.
B51: Préparez la glace pilée en déposant les glaçons dans un torchon.
B52: Refermez-le.
B53: À l’aide d’un pilon spécial cocktail, frappez fortement pour casser la glace.
B54: Ajoutez votre glace pilée dans le verre.
B55: Allongez votre cocktail avec du soda ou du sprite.

Sheet Sex on the beach cocktail
A9: FICHE TECHNIQUE
A11: Cocktail
A13: Sex on the beach
A15: Nombre de verres: | B15: 1
A17: Prix de vente TTC : | B17: =(B18*E41)+E41 -> 14.042993
A18: Taux TVA : | B18: 0.16
A20: Mode d'élaboration :
A21: Shaker
A22: Verre à mélange
A23: Direct au verre
A25: Type de verre utilisé: | B25: Verre à cocktail
A27: Article | B27: Unité | C27: Unités nécessaires | D27: Coût d'achat HT à l'unité | E27: Prix de revient HT
A28: ABSOLUT VODKA 75CL | B28: =_xlfn.XLOOKUP(Tableau5712314161820222426[[#This Row],[Article]],'Liste des fournisseurs'!$B$12:$B$307,'Liste des fournisseurs'!$C$12:$C$307,"") -> cl | C28: 8 | D28: =_xlfn.XLOOKUP(Tableau5712314161820222426[[#This Row],[Article]],'Liste des fournisseurs'!$B$12:$B$307,'Liste des fournisseurs'!$F$12:$F$307,"") -> 0.12 | E28: =IFERROR(Tableau5712314161820222426[[#This Row],[Coût d''achat HT à l''unité]]*Tableau5712314161820222426[[#This Row],[Unités nécessaires]],"") -> 0.96
A29: Jus d'Orange | B29: =_xlfn.XLOOKUP(Tableau5712314161820222426[[#This Row],[Article]],'Liste des fournisseurs'!$B$12:$B$307,'Liste des fournisseurs'!$C$12:$C$307,"") -> cl | C29: 5 | D29: =_xlfn.XLOOKUP(Tableau5712314161820222426[[#This Row],[Article]],'Liste des fournisseurs'!$B$12:$B$307,'Liste des fournisseurs'!$F$12:$F$307,"") -> 0.0286 | E29: =IFERROR(Tableau5712314161820222426[[#This Row],[Coût d''achat HT à l''unité]]*Tableau5712314161820222426[[#This Row],[Unités nécessaires]],"") -> 0.143
A30: Jus de Cranberry | B30: =_xlfn.XLOOKUP(Tableau5712314161820222426[[#This Row],[Article]],'Liste des fournisseurs'!$B$12:$B$307,'Liste des fournisseurs'!$C$12:$C$307,"") -> cl | C30: 5 | D30: =_xlfn.XLOOKUP(Tableau5712314161820222426[[#This Row],[Article]],'Liste des fournisseurs'!$B$12:$B$307,'Liste des fournisseurs'!$F$12:$F$307,"") -> 0.0286 | E30: =IFERROR(Tableau5712314161820222426[[#This Row],[Coût d''achat HT à l''unité]]*Tableau5712314161820222426[[#This Row],[Unités nécessaires]],"") -> 0.143
A31: Sirop de Grenadine | B31: =_xlfn.XLOOKUP(Tableau5712314161820222426[[#This Row],[Article]],'Liste des fournisseurs'!$B$12:$B$307,'Liste des fournisseurs'!$C$12:$C$307,"") -> cl | C31: 2 | D31: =_xlfn.XLOOKUP(Tableau5712314161820222426[[#This Row],[Article]],'Liste des fournisseurs'!$B$12:$B$307,'Liste des fournisseurs'!$F$12:$F$307,"") -> 0.11428571 | E31: =IFERROR(Tableau5712314161820222426[[#This Row],[Coût d''achat HT à l''unité]]*Tableau5712314161820222426[[#This Row],[Unités nécessaires]],"") -> 0.22857143
A32: Jus de citron | B32: =_xlfn.XLOOKUP(Tableau5712314161820222426[[#This Row],[Article]],'Liste des fournisseurs'!$B$12:$B$307,'Liste des fournisseurs'!$C$12:$C$307,"") -> cl | C32: 1 | D32: =_xlfn.XLOOKUP(Tableau5712314161820222426[[#This Row],[Article]],'Liste des fournisseurs'!$B$12:$B$307,'Liste des fournisseurs'!$F$12:$F$307,"") -> 0.02 | E32: =IFERROR(Tableau5712314161820222426[[#This Row],[Coût d''achat HT à l''unité]]*Tableau5712314161820222426[[#This Row],[Unités nécessaires]],"") -> 0.02
B33: =_xlfn.XLOOKUP(Tableau5712314161820222426[[#This Row],[Article]],'Liste des fournisseurs'!$B$12:$B$307,'Liste des fournisseurs'!$C$12:$C$307,"") | D33: =_xlfn.XLOOKUP(Tableau5712314161820222426[[#This Row],[Article]],'Liste des fournisseurs'!$B$12:$B$307,'Liste des fournisseurs'!$F$12:$F$307,"") | E33: =IFERROR(Tableau5712314161820222426[[#This Row],[Coût d''achat HT à l''unité]]*Tableau5712314161820222426[[#This Row],[Unités nécessaires]],"")
A34: Total prix de revient HT | E34: =SUM(Tableau5712314161820222426[Prix de revient HT]) -> 1.4945714
A35: Prix de revient unitaire HT par portion produite : | E35: =E34/B15 -> 1.4945714
A36: Pourcentage moyen d'invendus : | B36: 0.2 | E36: =SUM(E28:E33) -> 1.4945714
A37: Prix de revient unitaire HT par portion vendue : | E37: =E35+B36*E35 -> 1.7934857
A38: Coefficient de marge | E38: 6.75
A39: Taux de marque | E39: =(E41-E37)/E41 -> 0.85185185
A40: Référence taux de marque idéal | E40: 70%-90%
A41: Prix de vente HT | E41: =E37*E38 -> 12.106029
A42: Marge brute | E42: =E41-E37 -> 10.312543
A44: Technique de prépartion
A45: Munissez-vous d’un shaker et déposez-y quelques glaçons.
A46: Versez la vodka, le jus d'orange, et le jus de cranberry.
A47: Shakez le tout environ 15 secondes pour refroidir le mélange.

Sheet Cosmopolitan 
A9: FICHE TECHNIQUE
A11: Cocktail
A13: Cosmopolitan
A15: Nombre de verres: | B15: 1
A17: Prix de vente TTC : | B17: =(B18*E39)+E39 -> 13.959075
A18: Taux TVA : | B18: 0.16
A20: Mode d'élaboration :
A21: Shaker
A22: Verre à mélange
A23: Direct au verre
A25: Type de verre utilisé: | B25: Verre à cocktail
A27: Article | B27: Unité | C27: Unités nécessaires | D27: Coût d'achat HT à l'unité | E27: Prix de revient HT
A28: COINTREAU 70CL | B28: =_xlfn.XLOOKUP(Tableau5712314161820222432[[#This Row],[Article]],'Liste des fournisseurs'!$B$12:$B$307,'Liste des fournisseurs'!$C$12:$C$307,"") -> cl | C28: 3 | D28: =_xlfn.XLOOKUP(Tableau5712314161820222432[[#This Row],[Article]],'Liste des fournisseurs'!$B$12:$B$307,'Liste des fournisseurs'!$F$12:$F$307,"") -> 0.31428571 | E28: =IFERROR(Tableau5712314161820222432[[#This Row],[Coût d''achat HT à l''unité]]*Tableau5712314161820222432[[#This Row],[Unités nécessaires]],"") -> 0.94285714
A29: ABSOLUT VODKA 75CL | B29: =_xlfn.XLOOKUP(Tableau5712314161820222432[[#This Row],[Article]],'Liste des fournisseurs'!$B$12:$B$307,'Liste des fournisseurs'!$C$12:$C$307,"") -> cl | C29: 4 | D29: =_xlfn.XLOOKUP(Tableau5712314161820222432[[#This Row],[Article]],'Liste des fournisseurs'!$B$12:$B$307,'Liste des fournisseurs'!$F$12:$F$307,"") -> 0.12 | E29: =IFERROR(Tableau5712314161820222432[[#This Row],[Coût d''achat HT à l''unité]]*Tableau5712314161820222432[[#This Row],[Unités nécessaires]],"") -> 0.48
A30: FraiseSirop-70 | B30: =_xlfn.XLOOKUP(Tableau5712314161820222432[[#This Row],[Article]],'Liste des fournisseurs'!$B$12:$B$307,'Liste des fournisseurs'!$C$12:$C$307,"") -> cl | C30: 3 | D30: =_xlfn.XLOOKUP(Tableau5712314161820222432[[#This Row],[Article]],'Liste des fournisseurs'!$B$12:$B$307,'Liste des fournisseurs'!$F$12:$F$307,"") -> 0.12014286 | E30: =IFERROR(Tableau5712314161820222432[[#This Row],[Coût d''achat HT à l''unité]]*Tableau5712314161820222432[[#This Row],[Unités nécessaires]],"") -> 0.36042857
A31: Jus de citron | B31: =_xlfn.XLOOKUP(Tableau5712314161820222432[[#This Row],[Article]],'Liste des fournisseurs'!$B$12:$B$307,'Liste des fournisseurs'!$C$12:$C$307,"") -> cl | C31: 2 | D31: =_xlfn.XLOOKUP(Tableau5712314161820222432[[#This Row],[Article]],'Liste des fournisseurs'!$B$12:$B$307,'Liste des fournisseurs'!$F$12:$F$307,"") -> 0.02 | E31: =IFERROR(Tableau5712314161820222432[[#This Row],[Coût d''achat HT à l''unité]]*Tableau5712314161820222432[[#This Row],[Unités nécessaires]],"") -> 0.04
A32: Total prix de revient HT | E32: =SUM(Tableau5712314161820222432[Prix de revient HT]) -> 1.8232857
A33: Prix de revient unitaire HT par portion produite : | E33: =E32/B15 -> 1.8232857
A34: Pourcentage moyen d'invendus : | B34: 0.2 | E34: =SUM(E28:E31) -> 1.8232857
A35: Prix de revient unitaire HT par portion vendue : | E35: =E33+B34*E33 -> 2.1879429
A36: Coefficient de marge | E36: 5.5
A37: Taux de marque | E37: =(E39-E35)/E39 -> 0.81818182
A38: Référence taux de marque idéal | E38: 70%-90%
A39: Prix de vente HT | E39: =E35*E36 -> 12.033686
A40: Marge brute | E40: =E39-E35 -> 9.8457429
A42: Technique de prépartion
A43: Remplissez votre shaker à moitié de glaçons.
A44: Versez la vodka.
A45: Ajoutez le Cointreau et le sirop de fraise.
A46: Prenez un citron vert frais et pressez-le. Ajoutez-le aux autres ingrédients.
A47: Shakez le cocktail.
A48: Prenez un verre et munissez vous de la passoire à cocktail.
A49: Filtrez le contenu dans votre verre à cocktail.

Sheet Daïquiri 
B9: FICHE TECHNIQUE
B11: Cocktail
B13: Daïquiri
B15: Nombre de verres: | C15: 1
B17: Prix de vente TTC : | C17: =(C18*F38)+F38 -> 12.480274
B18: Taux TVA : | C18: 0.16
B20: Mode d'élaboration :
B21: Shaker
B22: Verre à mélange
B23: Direct au verre
B25: Type de verre utilisé: | C25: Verre à cocktail
B27: Article | C27: Unité | D27: Unités nécessaires | E27: Coût d'achat HT à l'unité | F27: Prix de revient HT
B28: RUM SAINT JAMES BLC 70CL | C28: =_xlfn.XLOOKUP(Tableau571231416182022243234[[#This Row],[Article]],'Liste des fournisseurs'!$B$12:$B$307,'Liste des fournisseurs'!$C$12:$C$307,"") -> cl | D28: 6 | E28: =_xlfn.XLOOKUP(Tableau571231416182022243234[[#This Row],[Article]],'Liste des fournisseurs'!$B$12:$B$307,'Liste des fournisseurs'!$F$12:$F$307,"") -> 0.17857143 | F28: =IFERROR(Tableau571231416182022243234[[#This Row],[Coût d''achat HT à l''unité]]*Tableau571231416182022243234[[#This Row],[Unités nécessaires]],"") -> 1.0714286
B29: Sirop de Sucre de canne-70 | C29: =_xlfn.XLOOKUP(Tableau571231416182022243234[[#This Row],[Article]],'Liste des fournisseurs'!$B$12:$B$307,'Liste des fournisseurs'!$C$12:$C$307,"") -> cl | D29: 2 | E29: =_xlfn.XLOOKUP(Tableau571231416182022243234[[#This Row],[Article]],'Liste des fournisseurs'!$B$12:$B$307,'Liste des fournisseurs'!$F$12:$F$307,"") -> 0.17142857 | F29: =IFERROR(Tableau571231416182022243234[[#This Row],[Coût d''achat HT à l''unité]]*Tableau571231416182022243234[[#This Row],[Unités nécessaires]],"") -> 0.34285714
B30: Jus de citron | C30: =_xlfn.XLOOKUP(Tableau571231416182022243234[[#This Row],[Article]],'Liste des fournisseurs'!$B$12:$B$307,'Liste des fournisseurs'!$C$12:$C$307,"") -> cl | D30: 4 | E30: =_xlfn.XLOOKUP(Tableau571231416182022243234[[#This Row],[Article]],'Liste des fournisseurs'!$B$12:$B$307,'Liste des fournisseurs'!$F$12:$F$307,"") -> 0.02 | F30: =IFERROR(Tableau571231416182022243234[[#This Row],[Coût d''achat HT à l''unité]]*Tableau571231416182022243234[[#This Row],[Unités nécessaires]],"") -> 0.08
B31: Total prix de revient HT | F31: =SUM(Tableau571231416182022243234[Prix de revient HT]) -> 1.4942857
B32: Prix de revient unitaire HT par portion produite : | F32: =F31/C15 -> 1.4942857
B33: Pourcentage moyen d'invendus : | C33: 0.2 | F33: =SUM(F28:F30) -> 1.4942857
B34: Prix de revient unitaire HT par portion vendue : | F34: =F32+C33*F32 -> 1.7931429
B35: Coefficient de marge | F35: 6
B36: Taux de marque | F36: =(F38-F34)/F38 -> 0.83333333
B37: Référence taux de marque idéal | F37: 70%-90%
B38: Prix de vente HT | F38: =F34*F35 -> 10.758857
B39: Marge brute | F39: =F38-F34 -> 8.9657143
B41: Technique de prépartion
B42: Munissez-vous d’un verre à cocktail et versez le rhum blanc, le jus de citron vert et le sucre de canne Canadou
B43: en mélangeant légèrement à l’aide d’une cuillère à mélange.
B44: Ajoutez 3 à 4 glaçons.
B45: Décorez le rebord du verre avec une rondelle de citron vert.

Sheet TEQUILA SUNRISE
B8: FICHE TECHNIQUE
B10: Cocktail
B12: TEQUILA SUNRISE
B14: Nombre de verres: | C14: 1
B16: Prix de vente TTC : | C16: =(C17*F37)+F37 -> 10.083847
B17: Taux TVA : | C17: 0.16
B19: Mode d'élaboration :
B20: Shaker
B21: Verre à mélange
B22: Direct au verre
B24: Type de verre utilisé: | C24: Verre
B26: Article | C26: Unité | D26: Unités nécessaires | E26: Coût d'achat HT à l'unité | F26: Prix de revient HT
B27: Jus d'Orange | C27: =_xlfn.XLOOKUP(Tableau57123141618202224323436[[#This Row],[Article]],'Liste des fournisseurs'!$B$12:$B$307,'Liste des fournisseurs'!$C$12:$C$307,"") -> cl | D27: 9 | E27: =_xlfn.XLOOKUP(Tableau57123141618202224323436[[#This Row],[Article]],'Liste des fournisseurs'!$B$12:$B$307,'Liste des fournisseurs'!$F$12:$F$307,"") -> 0.0286 | F27: =IFERROR(Tableau57123141618202224323436[[#This Row],[Coût d''achat HT à l''unité]]*Tableau57123141618202224323436[[#This Row],[Unités nécessaires]],"") -> 0.2574
B28: CAMINO BLC 75CL | C28: =_xlfn.XLOOKUP(Tableau57123141618202224323436[[#This Row],[Article]],'Liste des fournisseurs'!$B$12:$B$307,'Liste des fournisseurs'!$C$12:$C$307,"") -> cl | D28: 4.5 | E28: =_xlfn.XLOOKUP(Tableau57123141618202224323436[[#This Row],[Article]],'Liste des fournisseurs'!$B$12:$B$307,'Liste des fournisseurs'!$F$12:$F$307,"") -> 0.22666667 | F28: =IFERROR(Tableau57123141618202224323436[[#This Row],[Coût d''achat HT à l''unité]]*Tableau57123141618202224323436[[#This Row],[Unités nécessaires]],"") -> 1.02
B29: Sirop de Grenadine | C29: =_xlfn.XLOOKUP(Tableau57123141618202224323436[[#This Row],[Article]],'Liste des fournisseurs'!$B$12:$B$307,'Liste des fournisseurs'!$C$12:$C$307,"") -> cl | D29: 1.5 | E29: =_xlfn.XLOOKUP(Tableau57123141618202224323436[[#This Row],[Article]],'Liste des fournisseurs'!$B$12:$B$307,'Liste des fournisseurs'!$F$12:$F$307,"") -> 0.11428571 | F29: =IFERROR(Tableau57123141618202224323436[[#This Row],[Coût d''achat HT à l''unité]]*Tableau57123141618202224323436[[#This Row],[Unités nécessaires]],"") -> 0.17142857
B30: Total prix de revient HT | F30: =SUM(Tableau57123141618202224323436[Prix de revient HT]) -> 1.4488286
B31: Prix de revient unitaire HT par portion produite : | F31: =F30/C14 -> 1.4488286
B32: Pourcentage moyen d'invendus : | C32: 0.2 | F32: =SUM(F27:F29) -> 1.4488286
B33: Prix de revient unitaire HT par portion vendue : | F33: =F31+C32*F31 -> 1.7385943
B34: Coefficient de marge | F34: 5
B35: Taux de marque | F35: =(F37-F33)/F37 -> 0.8
B36: Référence taux de marque idéal | F36: 70%-90%
B37: Prix de vente HT | F37: =F33*F34 -> 8.6929714
B38: Marge brute | F38: =F37-F33 -> 6.9543771
B40: Technique de prépartion
B41: Mettez des glaçons dans un verre long drink.
B42: Versez dans l’ordre la Tequila puis le jus d’orange.
B43: Remuez doucement à l’aide d’une cuillère à mélange.
B44: Versez lentement le sirop de grenadine en vérifiant que le sirop tombe bien au fond du verre.
B45: Donnez un petit coup de cuillère à cocktail pour créer un joli dégradé typique du Tequila Sunrise.

Sheet LONG ISLAND
B7: FICHE TECHNIQUE
B9: Cocktail
B11: Long Island
B13: Nombre de verres: | C13: 1
B15: Prix de vente TTC : | C15: =(C16*F40)+F40 -> 17.868602
B16: Taux TVA : | C16: 0.16
B18: Mode d'élaboration :
B19: Shaker
B20: Verre à mélange
B21: Direct au verre
B23: Type de verre utilisé: | C23: Verre long drink
B25: Article | C25: Unité | D25: Unités nécessaires | E25: Coût d'achat HT à l'unité | F25: Prix de revient HT
B26: RUM SAINT JAMES BLC 70CL | C26: =_xlfn.XLOOKUP(Tableau571231416182022243234362[[#This Row],[Article]],'Liste des fournisseurs'!$B$12:$B$307,'Liste des fournisseurs'!$C$12:$C$307,"") -> cl | D26: 2 | E26: =_xlfn.XLOOKUP(Tableau571231416182022243234362[[#This Row],[Article]],'Liste des fournisseurs'!$B$12:$B$307,'Liste des fournisseurs'!$F$12:$F$307,"") -> 0.17857143 | F26: =IFERROR(Tableau571231416182022243234362[[#This Row],[Coût d''achat HT à l''unité]]*Tableau571231416182022243234362[[#This Row],[Unités nécessaires]],"") -> 0.35714286
B27: VODKA ABSOLUT 750ML | C27: =_xlfn.XLOOKUP(Tableau571231416182022243234362[[#This Row],[Article]],'Liste des fournisseurs'!$B$12:$B$307,'Liste des fournisseurs'!$C$12:$C$307,"") -> CL | D27: 2 | E27: =_xlfn.XLOOKUP(Tableau571231416182022243234362[[#This Row],[Article]],'Liste des fournisseurs'!$B$12:$B$307,'Liste des fournisseurs'!$F$12:$F$307,"") -> 0.10666667 | F27: =IFERROR(Tableau571231416182022243234362[[#This Row],[Coût d''achat HT à l''unité]]*Tableau571231416182022243234362[[#This Row],[Unités nécessaires]],"") -> 0.21333333
B28: HENDRICKS GIN 700ML | C28: =_xlfn.XLOOKUP(Tableau571231416182022243234362[[#This Row],[Article]],'Liste des fournisseurs'!$B$12:$B$307,'Liste des fournisseurs'!$C$12:$C$307,"") -> cl | D28: 3 | E28: =_xlfn.XLOOKUP(Tableau571231416182022243234362[[#This Row],[Article]],'Liste des fournisseurs'!$B$12:$B$307,'Liste des fournisseurs'!$F$12:$F$307,"") -> 0.45 | F28: =IFERROR(Tableau571231416182022243234362[[#This Row],[Coût d''achat HT à l''unité]]*Tableau571231416182022243234362[[#This Row],[Unités nécessaires]],"") -> 1.35
B29: Sirop de Sucre de canne-70 | C29: =_xlfn.XLOOKUP(Tableau571231416182022243234362[[#This Row],[Article]],'Liste des fournisseurs'!$B$12:$B$307,'Liste des fournisseurs'!$C$12:$C$307,"") -> cl | D29: 1 | E29: =_xlfn.XLOOKUP(Tableau571231416182022243234362[[#This Row],[Article]],'Liste des fournisseurs'!$B$12:$B$307,'Liste des fournisseurs'!$F$12:$F$307,"") -> 0.17142857 | F29: =IFERROR(Tableau571231416182022243234362[[#This Row],[Coût d''achat HT à l''unité]]*Tableau571231416182022243234362[[#This Row],[Unités nécessaires]],"") -> 0.17142857
B30: CAMINO TEQUILA BLC 75CL | C30: =_xlfn.XLOOKUP(Tableau571231416182022243234362[[#This Row],[Article]],'Liste des fournisseurs'!$B$12:$B$307,'Liste des fournisseurs'!$C$12:$C$307,"") -> cl | D30: 2 | E30: =_xlfn.XLOOKUP(Tableau571231416182022243234362[[#This Row],[Article]],'Liste des fournisseurs'!$B$12:$B$307,'Liste des fournisseurs'!$F$12:$F$307,"") -> 0.17333333 | F30: =IFERROR(Tableau571231416182022243234362[[#This Row],[Coût d''achat HT à l''unité]]*Tableau571231416182022243234362[[#This Row],[Unités nécessaires]],"") -> 0.34666667
B31: BARD LIQ TRIPLE SEC 70CL | C31: =_xlfn.XLOOKUP(Tableau571231416182022243234362[[#This Row],[Article]],'Liste des fournisseurs'!$B$12:$B$307,'Liste des fournisseurs'!$C$12:$C$307,"") -> cl | D31: 1.5 | E31: =_xlfn.XLOOKUP(Tableau571231416182022243234362[[#This Row],[Article]],'Liste des fournisseurs'!$B$12:$B$307,'Liste des fournisseurs'!$F$12:$F$307,"") -> 0.175 | F31: =IFERROR(Tableau571231416182022243234362[[#This Row],[Coût d''achat HT à l''unité]]*Tableau571231416182022243234362[[#This Row],[Unités nécessaires]],"") -> 0.2625
B32: Coca Cola | C32: =_xlfn.XLOOKUP(Tableau571231416182022243234362[[#This Row],[Article]],'Liste des fournisseurs'!$B$12:$B$307,'Liste des fournisseurs'!$C$12:$C$307,"") -> cl | D32: 10 | E32: =_xlfn.XLOOKUP(Tableau571231416182022243234362[[#This Row],[Article]],'Liste des fournisseurs'!$B$12:$B$307,'Liste des fournisseurs'!$F$12:$F$307,"") -> 0.015151515 | F32: =IFERROR(Tableau571231416182022243234362[[#This Row],[Coût d''achat HT à l''unité]]*Tableau571231416182022243234362[[#This Row],[Unités nécessaires]],"") -> 0.15151515
B33: Total prix de revient HT | F33: =SUM(Tableau571231416182022243234362[Prix de revient HT]) -> 2.8525866
B34: Prix de revient unitaire HT par portion produite : | F34: =F33/C13 -> 2.8525866
B35: Pourcentage moyen d'invendus : | C35: 0.2 | F35: =SUM(F26:F32) -> 2.8525866
B36: Prix de revient unitaire HT par portion vendue : | F36: =F34+C35*F34 -> 3.4231039
B37: Coefficient de marge | F37: 4.5
B38: Taux de marque | F38: =(F40-F36)/F40 -> 0.77777778
B39: Référence taux de marque idéal | F39: 70%-90%
B40: Prix de vente HT | F40: =F36*F37 -> 15.403968
B41: Marge brute | F41: =F40-F36 -> 11.980864
B43: Technique de prépartion
B44: Ajoutez la vodka, la tequila , le rhum blanc, le gin et le triple sec dans un shaker avec des glaçons.
B45: Versez dans votre shaker le jus de citron jaune et le sirop de sucre de canne.
B46: Secouez énergiquement pendant une dizaine de secondes.
B47: Munissez-vous d’un verre long drink.
B48: Incorporez votre mélange en filtrant les glaçons à l’aide d’une passoire à cocktail.
B49: Versez un trait de cola jusqu’au remplissage complet du verre.

Sheet Espresso Martini
B7: FICHE TECHNIQUE
B9: Cocktail
B11: Espresso Martini
B13: Nombre de verres: | C13: 1
B15: Prix de vente TTC : | C15: =(C16*F39)+F39 -> 14.991177
B16: Taux TVA : | C16: 0.16
B18: Mode d'élaboration :
B19: Shaker :
B20: Verre à mélange :
B21: Direct au verre :
B22: Blender :
B24: Type de verre utilisé: | C24: Verre à cocktail
B26: Article | C26: Unité | D26: Unités nécessaires | E26: Coût d'achat HT à l'unité | F26: Prix de revient HT
B27: Patrón XO Café | C27: cl | D27: 2 | E27: =_xlfn.XLOOKUP(Tableau5712314161820222432343626[[#This Row],[Article]],'Liste des fournisseurs'!$B$12:$B$307,'Liste des fournisseurs'!$F$12:$F$307,"") -> 0.53333333 | F27: =IFERROR(Tableau5712314161820222432343626[[#This Row],[Coût d''achat HT à l''unité]]*Tableau5712314161820222432343626[[#This Row],[Unités nécessaires]],"") -> 1.0666667
B28: Espresso | C28: cl | D28: 3 | E28: 0.1 | F28: =IFERROR(Tableau5712314161820222432343626[[#This Row],[Coût d''achat HT à l''unité]]*Tableau5712314161820222432343626[[#This Row],[Unités nécessaires]],"") -> 0.3
B29: ABSOLUT VODKA 75CL | C29: cl | D29: 3.5 | E29: =_xlfn.XLOOKUP(Tableau5712314161820222432343626[[#This Row],[Article]],'Liste des fournisseurs'!$B$12:$B$307,'Liste des fournisseurs'!$F$12:$F$307,"") -> 0.12 | F29: =IFERROR(Tableau5712314161820222432343626[[#This Row],[Coût d''achat HT à l''unité]]*Tableau5712314161820222432343626[[#This Row],[Unités nécessaires]],"") -> 0.42
B30: Sirop de Sucre de canne-70 | C30: cl | D30: 1 | E30: =_xlfn.XLOOKUP(Tableau5712314161820222432343626[[#This Row],[Article]],'Liste des fournisseurs'!$B$12:$B$307,'Liste des fournisseurs'!$F$12:$F$307,"") -> 0.17142857 | F30: =IFERROR(Tableau5712314161820222432343626[[#This Row],[Coût d''achat HT à l''unité]]*Tableau5712314161820222432343626[[#This Row],[Unités nécessaires]],"") -> 0.17142857
E31: =_xlfn.XLOOKUP(Tableau5712314161820222432343626[[#This Row],[Article]],'Liste des fournisseurs'!$B$12:$B$307,'Liste des fournisseurs'!$F$12:$F$307,"") | F31: =IFERROR(Tableau5712314161820222432343626[[#This Row],[Coût d''achat HT à l''unité]]*Tableau5712314161820222432343626[[#This Row],[Unités nécessaires]],"")
B32: Total prix de revient HT | F32: =SUM(Tableau5712314161820222432343626[Prix de revient HT]) -> 1.9580952
B33: Prix de revient unitaire HT par portion produite : | F33: =F32/C13 -> 1.9580952
B34: Pourcentage moyen d'invendus : | C34: 0.2 | F34: =SUM(F27:F31) -> 1.9580952
B35: Prix de revient unitaire HT par portion vendue : | F35: =F33+C34*F33 -> 2.3497143
B36: Coefficient de marge | F36: 5.5
B37: Taux de marque | F37: =(F39-F35)/F39 -> 0.81818182
B38: Référence taux de marque idéal | F38: 70%-90%
B39: Prix de vente HT | F39: =F35*F36 -> 12.923429
B40: Marge brute | F40: =F39-F35 -> 10.573714
B42: Technique de prépartion
B43: Préparez un expresso fort et laissez-le refroidir complètement.
B44: Mettez à refroidir votre verre à cocktail.
B45: Ajoutez la vodka, le café espresso refroidi, la liqueur de café et l'Amarula.
B46: Secouez vigoureusement pendant environ 10 à 15 secondes pour bien mélanger les ingrédients.
B47: Incorporez votre mélange en filtrant les glaçons à l’aide d’une passoire à cocktail.

Sheet Caïpirinha
B7: FICHE TECHNIQUE
B9: Cocktail
B11: Caïpirinha
B13: Nombre de verres: | C13: 1
B15: Prix de vente TTC : | C15: =(C16*F39)+F39 -> 12.19421
B16: Taux TVA : | C16: 0.16
B18: Mode d'élaboration :
B19: Shaker
B20: Verre à mélange
B21: Direct au verre
B23: Type de verre utilisé: | C23: Verre old fashioned
B25: Article | C25: Unité | D25: Unités nécessaires | E25: Coût d'achat HT à l'unité | F25: Prix de revient HT
B26: Sucre Brun | C26: =_xlfn.XLOOKUP(Tableau57123141618202224323436210[[#This Row],[Article]],'Liste des fournisseurs'!$B$12:$B$307,'Liste des fournisseurs'!$C$12:$C$307,"") -> g | D26: 2 | E26: =_xlfn.XLOOKUP(Tableau57123141618202224323436210[[#This Row],[Article]],'Liste des fournisseurs'!$B$12:$B$307,'Liste des fournisseurs'!$F$12:$F$307,"") -> 0.00138 | F26: =IFERROR(Tableau57123141618202224323436210[[#This Row],[Coût d''achat HT à l''unité]]*Tableau57123141618202224323436210[[#This Row],[Unités nécessaires]],"") -> 0.00276
B27: citron | C27: =_xlfn.XLOOKUP(Tableau57123141618202224323436210[[#This Row],[Article]],'Liste des fournisseurs'!$B$12:$B$307,'Liste des fournisseurs'!$C$12:$C$307,"") -> unité | D27: 1 | E27: =_xlfn.XLOOKUP(Tableau57123141618202224323436210[[#This Row],[Article]],'Liste des fournisseurs'!$B$12:$B$307,'Liste des fournisseurs'!$F$12:$F$307,"") -> 0.38496436 | F27: =IFERROR(Tableau57123141618202224323436210[[#This Row],[Coût d''achat HT à l''unité]]*Tableau57123141618202224323436210[[#This Row],[Unités nécessaires]],"") -> 0.38496436
B28: AGUACANA CACHACA 75cl | C28: =_xlfn.XLOOKUP(Tableau57123141618202224323436210[[#This Row],[Article]],'Liste des fournisseurs'!$B$12:$B$307,'Liste des fournisseurs'!$C$12:$C$307,"") -> cl | D28: 6 | E28: =_xlfn.XLOOKUP(Tableau57123141618202224323436210[[#This Row],[Article]],'Liste des fournisseurs'!$B$12:$B$307,'Liste des fournisseurs'!$F$12:$F$307,"") -> 0.16 | F28: =IFERROR(Tableau57123141618202224323436210[[#This Row],[Coût d''achat HT à l''unité]]*Tableau57123141618202224323436210[[#This Row],[Unités nécessaires]],"") -> 0.96
C29: =_xlfn.XLOOKUP(Tableau57123141618202224323436210[[#This Row],[Article]],'Liste des fournisseurs'!$B$12:$B$307,'Liste des fournisseurs'!$C$12:$C$307,"") | D29: 2 | E29: =_xlfn.XLOOKUP(Tableau57123141618202224323436210[[#This Row],[Article]],'Liste des fournisseurs'!$B$12:$B$307,'Liste des fournisseurs'!$F$12:$F$307,"") | F29: =IFERROR(Tableau57123141618202224323436210[[#This Row],[Coût d''achat HT à l''unité]]*Tableau57123141618202224323436210[[#This Row],[Unités nécessaires]],"")
C30: =_xlfn.XLOOKUP(Tableau57123141618202224323436210[[#This Row],[Article]],'Liste des fournisseurs'!$B$12:$B$307,'Liste des fournisseurs'!$C$12:$C$307,"") | E30: =_xlfn.XLOOKUP(Tableau57123141618202224323436210[[#This Row],[Article]],'Liste des fournisseurs'!$B$12:$B$307,'Liste des fournisseurs'!$F$12:$F$307,"") | F30: =IFERROR(Tableau57123141618202224323436210[[#This Row],[Coût d''achat HT à l''unité]]*Tableau57123141618202224323436210[[#This Row],[Unités nécessaires]],"")
C31: =_xlfn.XLOOKUP(Tableau57123141618202224323436210[[#This Row],[Article]],'Liste des fournisseurs'!$B$12:$B$307,'Liste des fournisseurs'!$C$12:$C$307,"") | E31: =_xlfn.XLOOKUP(Tableau57123141618202224323436210[[#This Row],[Article]],'Liste des fournisseurs'!$B$12:$B$307,'Liste des fournisseurs'!$F$12:$F$307,"") | F31: =IFERROR(Tableau57123141618202224323436210[[#This Row],[Coût d''achat HT à l''unité]]*Tableau57123141618202224323436210[[#This Row],[Unités nécessaires]],"")
B32: Total prix de revient HT | F32: =SUM(Tableau57123141618202224323436210[Prix de revient HT]) -> 1.3477244
B33: Prix de revient unitaire HT par portion produite : | F33: =F32/C13 -> 1.3477244
B34: Pourcentage moyen d'invendus : | C34: 0.2 | F34: =SUM(F26:F31) -> 1.3477244
B35: Prix de revient unitaire HT par portion vendue : | F35: =F33+C34*F33 -> 1.6172692
B36: Coefficient de marge | F36: 6.5
B37: Taux de marque | F37: =(F39-F35)/F39 -> 0.84615385
B38: Référence taux de marque idéal | F38: 70%-90%
B39: Prix de vente HT | F39: =F35*F36 -> 10.51225
B40: Marge brute | F40: =F39-F35 -> 8.8949808
B43: Technique de prépartion
B44: Lavez le citron puis coupez-le en deux dans le sens de la hauteur.
B45: Enlevez la partie blanche centrale, source d’amertume.
B46: Découpez le citron en petits dés et placez-les dans un verre old fashioned.
B47: Ecrasez à l’aide d’un pilon pour extraire le jus du citron vert.
B48: Ajoutez la glace pilée dans le verre.
B49: Versez le sirop de canne Canadou et la cachaça Aguacana.
B50: Mélangez avec une cuillère à mélange et servez avec une paille

Sheet Margarita
B7: FICHE TECHNIQUE
B9: Cocktail
B11: Margarita
B13: Nombre de verres: | C13: 1
B15: Prix de vente TTC : | C15: =(C16*F37)+F37 -> 9.92728
B16: Taux TVA : | C16: 0.16
B18: Mode d'élaboration :
B19: Shaker
B20: Verre à mélange
B21: Direct au verre
B23: Type de verre utilisé: | C23: Verre à Margarita
B25: Article | C25: Unité | D25: Unités nécessaires | E25: Coût d'achat HT à l'unité | F25: Prix de revient HT
B26: CAMINO BLC 75CL | C26: =_xlfn.XLOOKUP(Tableau5712314161820222432343638[[#This Row],[Article]],'Liste des fournisseurs'!$B$12:$B$307,'Liste des fournisseurs'!$C$12:$C$307,"") -> cl | D26: 4 | E26: =_xlfn.XLOOKUP(Tableau5712314161820222432343638[[#This Row],[Article]],'Liste des fournisseurs'!$B$12:$B$307,'Liste des fournisseurs'!$F$12:$F$307,"") -> 0.22666667 | F26: =IFERROR(Tableau5712314161820222432343638[[#This Row],[Coût d''achat HT à l''unité]]*Tableau5712314161820222432343638[[#This Row],[Unités nécessaires]],"") -> 0.90666667
B27: BARD LIQ TRIPLE SEC 70CL | C27: =_xlfn.XLOOKUP(Tableau5712314161820222432343638[[#This Row],[Article]],'Liste des fournisseurs'!$B$12:$B$307,'Liste des fournisseurs'!$C$12:$C$307,"") -> cl | D27: 2 | E27: =_xlfn.XLOOKUP(Tableau5712314161820222432343638[[#This Row],[Article]],'Liste des fournisseurs'!$B$12:$B$307,'Liste des fournisseurs'!$F$12:$F$307,"") -> 0.175 | F27: =IFERROR(Tableau5712314161820222432343638[[#This Row],[Coût d''achat HT à l''unité]]*Tableau5712314161820222432343638[[#This Row],[Unités nécessaires]],"") -> 0.35
B28: Jus de citron | C28: =_xlfn.XLOOKUP(Tableau5712314161820222432343638[[#This Row],[Article]],'Liste des fournisseurs'!$B$12:$B$307,'Liste des fournisseurs'!$C$12:$C$307,"") -> cl | D28: 2 | E28: =_xlfn.XLOOKUP(Tableau5712314161820222432343638[[#This Row],[Article]],'Liste des fournisseurs'!$B$12:$B$307,'Liste des fournisseurs'!$F$12:$F$307,"") -> 0.02 | F28: =IFERROR(Tableau5712314161820222432343638[[#This Row],[Coût d''achat HT à l''unité]]*Tableau5712314161820222432343638[[#This Row],[Unités nécessaires]],"") -> 0.04
C29: =_xlfn.XLOOKUP(Tableau5712314161820222432343638[[#This Row],[Article]],'Liste des fournisseurs'!$B$12:$B$307,'Liste des fournisseurs'!$C$12:$C$307,"") | E29: =_xlfn.XLOOKUP(Tableau5712314161820222432343638[[#This Row],[Article]],'Liste des fournisseurs'!$B$12:$B$307,'Liste des fournisseurs'!$F$12:$F$307,"") | F29: =IFERROR(Tableau5712314161820222432343638[[#This Row],[Coût d''achat HT à l''unité]]*Tableau5712314161820222432343638[[#This Row],[Unités nécessaires]],"")
B30: Total prix de revient HT | F30: =SUM(Tableau5712314161820222432343638[Prix de revient HT]) -> 1.2966667
B31: Prix de revient unitaire HT par portion produite : | F31: =F30/C13 -> 1.2966667
B32: Pourcentage moyen d'invendus : | C32: 0.2 | F32: =SUM(F26:F29) -> 1.2966667
B33: Prix de revient unitaire HT par portion vendue : | F33: =F31+C32*F31 -> 1.556
B34: Coefficient de marge | F34: 5.5
B35: Taux de marque | F35: =(F37-F33)/F37 -> 0.81818182
B36: Référence taux de marque idéal | F36: 70%-90%
B37: Prix de vente HT | F37: =F33*F34 -> 8.558
B38: Marge brute | F38: =F37-F33 -> 7.002
B40: Technique de prépartion
B41: Givrez le bord du verre en passant un quartier de citron vert sur le pourtour, puis trempez-le dans une assiette avec du sel fin.
B42: Versez tous les ingrédients dans un shaker avec des glaçons.
B43: Secouez énergiquement puis filtrez le cocktail dans le verre.
B44: Décorez avec un quartier de citron vert. Servez.

Sheet Negroni
B7: FICHE TECHNIQUE
B9: Cocktail
B11: Negroni
B13: Nombre de verres: | C13: 1
B15: Prix de vente TTC : | C15: =(C16*F38)+F38 -> 17.769576
B16: Taux TVA : | C16: 0.16
B18: Mode d'élaboration :
B19: Shaker
B20: Verre à mélange
B21: Direct au verre
B24: Type de verre utilisé: | C24: Verre old fashioned
B26: Article | C26: Unité | D26: Unités nécessaires | E26: Coût d'achat HT à l'unité | F26: Prix de revient HT
B27: HENDRICKS GIN 700ML | C27: =_xlfn.XLOOKUP(Tableau571231416182022243234363812[[#This Row],[Article]],'Liste des fournisseurs'!$B$12:$B$307,'Liste des fournisseurs'!$C$12:$C$307,"") -> cl | D27: =3*$C$13 -> 3 | E27: =_xlfn.XLOOKUP(Tableau571231416182022243234363812[[#This Row],[Article]],'Liste des fournisseurs'!$B$12:$B$307,'Liste des fournisseurs'!$F$12:$F$307,"") -> 0.45 | F27: =IFERROR(Tableau571231416182022243234363812[[#This Row],[Coût d''achat HT à l''unité]]*Tableau571231416182022243234363812[[#This Row],[Unités nécessaires]],"") -> 1.35
B28: CAMPARI 1L | C28: =_xlfn.XLOOKUP(Tableau571231416182022243234363812[[#This Row],[Article]],'Liste des fournisseurs'!$B$12:$B$307,'Liste des fournisseurs'!$C$12:$C$307,"") -> cl | D28: =3*$C$13 -> 3 | E28: =_xlfn.XLOOKUP(Tableau571231416182022243234363812[[#This Row],[Article]],'Liste des fournisseurs'!$B$12:$B$307,'Liste des fournisseurs'!$F$12:$F$307,"") -> 0.205 | F28: =IFERROR(Tableau571231416182022243234363812[[#This Row],[Coût d''achat HT à l''unité]]*Tableau571231416182022243234363812[[#This Row],[Unités nécessaires]],"") -> 0.615
B29: MARTINI ROSSO 75CL | C29: =_xlfn.XLOOKUP(Tableau571231416182022243234363812[[#This Row],[Article]],'Liste des fournisseurs'!$B$12:$B$307,'Liste des fournisseurs'!$C$12:$C$307,"") -> cl | D29: =3*$C$13 -> 3 | E29: =_xlfn.XLOOKUP(Tableau571231416182022243234363812[[#This Row],[Article]],'Liste des fournisseurs'!$B$12:$B$307,'Liste des fournisseurs'!$F$12:$F$307,"") -> 0.11866667 | F29: =IFERROR(Tableau571231416182022243234363812[[#This Row],[Coût d''achat HT à l''unité]]*Tableau571231416182022243234363812[[#This Row],[Unités nécessaires]],"") -> 0.356
C30: =_xlfn.XLOOKUP(Tableau571231416182022243234363812[[#This Row],[Article]],'Liste des fournisseurs'!$B$12:$B$307,'Liste des fournisseurs'!$C$12:$C$307,"") | E30: =_xlfn.XLOOKUP(Tableau571231416182022243234363812[[#This Row],[Article]],'Liste des fournisseurs'!$B$12:$B$307,'Liste des fournisseurs'!$F$12:$F$307,"") | F30: =IFERROR(Tableau571231416182022243234363812[[#This Row],[Coût d''achat HT à l''unité]]*Tableau571231416182022243234363812[[#This Row],[Unités nécessaires]],"")
B31: Total prix de revient HT | F31: =SUM(Tableau571231416182022243234363812[Prix de revient HT]) -> 2.321
B32: Prix de revient unitaire HT par portion produite : | F32: =F31/C13 -> 2.321
B33: Pourcentage moyen d'invendus : | C33: 0.2 | F33: =SUM(F27:F30) -> 2.321
B34: Prix de revient unitaire HT par portion vendue : | F34: =F32+C33*F32 -> 2.7852
B35: Coefficient de marge | F35: 5.5
B36: Taux de marque | F36: =(F38-F34)/F38 -> 0.81818182
B37: Référence taux de marque idéal | F37: 70%-90%
B38: Prix de vente HT | F38: =F34*F35 -> 15.3186
B39: Marge brute | F39: =F38-F34 -> 12.5334
B42: Technique de prépartion
B43: Dans un verre old fashioned, déposez les glaçons
B44: Ajoutez le gin, le vermouth rouge, le Campari et la demi-tranche d’orange.

Sheet Old Fashioned
B7: FICHE TECHNIQUE
B9: Cocktail
B11: Old Fashioned
B13: Nombre de verres: | C13: 1
B15: Prix de vente TTC : | C15: =(C16*F38)+F38 -> 17.026944
B16: Taux TVA : | C16: 0.16
B18: Mode d'élaboration :
B19: Shaker
B20: Verre à mélange
B21: Direct au verre
B24: Type de verre utilisé: | C24: Verre old fashioned
B26: Article | C26: Unité | D26: Unités nécessaires | E26: Coût d'achat HT à l'unité | F26: Prix de revient HT
B27: DOUBLE BLACK 75CL | C27: =_xlfn.XLOOKUP(Tableau5712314161820222432343638123[[#This Row],[Article]],'Liste des fournisseurs'!$B$12:$B$307,'Liste des fournisseurs'!$C$12:$C$307,"") -> cl | D27: 6 | E27: =_xlfn.XLOOKUP(Tableau5712314161820222432343638123[[#This Row],[Article]],'Liste des fournisseurs'!$B$12:$B$307,'Liste des fournisseurs'!$F$12:$F$307,"") -> 0.41466667 | F27: =IFERROR(Tableau5712314161820222432343638123[[#This Row],[Coût d''achat HT à l''unité]]*Tableau5712314161820222432343638123[[#This Row],[Unités nécessaires]],"") -> 2.488
B28: BARD LIQ TRIPLE SEC 70CL | C28: =_xlfn.XLOOKUP(Tableau5712314161820222432343638123[[#This Row],[Article]],'Liste des fournisseurs'!$B$12:$B$307,'Liste des fournisseurs'!$C$12:$C$307,"") -> cl | D28: 1.5 | E28: =_xlfn.XLOOKUP(Tableau5712314161820222432343638123[[#This Row],[Article]],'Liste des fournisseurs'!$B$12:$B$307,'Liste des fournisseurs'!$F$12:$F$307,"") -> 0.175 | F28: =IFERROR(Tableau5712314161820222432343638123[[#This Row],[Coût d''achat HT à l''unité]]*Tableau5712314161820222432343638123[[#This Row],[Unités nécessaires]],"") -> 0.2625
B29: CAMPARI 1L | C29: =_xlfn.XLOOKUP(Tableau5712314161820222432343638123[[#This Row],[Article]],'Liste des fournisseurs'!$B$12:$B$307,'Liste des fournisseurs'!$C$12:$C$307,"") -> cl | D29: 1.5 | E29: =_xlfn.XLOOKUP(Tableau5712314161820222432343638123[[#This Row],[Article]],'Liste des fournisseurs'!$B$12:$B$307,'Liste des fournisseurs'!$F$12:$F$307,"") -> 0.205 | F29: =IFERROR(Tableau5712314161820222432343638123[[#This Row],[Coût d''achat HT à l''unité]]*Tableau5712314161820222432343638123[[#This Row],[Unités nécessaires]],"") -> 0.3075
C30: =_xlfn.XLOOKUP(Tableau5712314161820222432343638123[[#This Row],[Article]],'Liste des fournisseurs'!$B$12:$B$307,'Liste des fournisseurs'!$C$12:$C$307,"") | E30: =_xlfn.XLOOKUP(Tableau5712314161820222432343638123[[#This Row],[Article]],'Liste des fournisseurs'!$B$12:$B$307,'Liste des fournisseurs'!$F$12:$F$307,"") | F30: =IFERROR(Tableau5712314161820222432343638123[[#This Row],[Coût d''achat HT à l''unité]]*Tableau5712314161820222432343638123[[#This Row],[Unités nécessaires]],"")
B31: Total prix de revient HT | F31: =SUM(Tableau5712314161820222432343638123[Prix de revient HT]) -> 3.058
B32: Prix de revient unitaire HT par portion produite : | F32: =F31/C13 -> 3.058
B33: Pourcentage moyen d'invendus : | C33: 0.2 | F33: =SUM(F27:F30) -> 3.058
B34: Prix de revient unitaire HT par portion vendue : | F34: =F32+C33*F32 -> 3.6696
B35: Coefficient de marge | F35: 4
B36: Taux de marque | F36: =(F38-F34)/F38 -> 0.75
B37: Référence taux de marque idéal | F37: 70%-90%
B38: Prix de vente HT | F38: =F34*F35 -> 14.6784
B39: Marge brute | F39: =F38-F34 -> 11.0088
B42: Technique de prépartion

Sheet Pop Cola mocktail
B7: FICHE TECHNIQUE
B9: Mocktail
B11: Pop Cola
